Workbook

Sheet Sales_Data
A1: ID | B1: Month | C1: Month Year | D1: Market | E1: Channel | F1: SKU | G1: SKU-MARKET | H1: Units_Sold | I1: Selling_Price_USD | J1: Revenue USD | K1: COGS_USD | L1: Gross_Margin_USD | M1: Gross_Margin_% | N1: Promotion_Flag | O1: Promo_Discount_% | P1: Campaign_Name | Q1: Data_Type
A2: 1 | B2: January | C2: 45658 | D2: USA | E2: Sephora | F2: Vanilla 28 | G2: =_xlfn.CONCAT(F2,"-",D2,) -> Vanilla 28-USA | H2: =ROUND(J2/I2,0) -> 19250 | I2: =VLOOKUP(G2,Table4[[SKU-COUNTRY2]:[Price in USD]],2,FALSE) -> 105 | J2: =VLOOKUP(G2,Sheet3!$C$82:$I$100,MATCH(E2,Sheet3!C$82:H$82,0),FALSE) * VLOOKUP(C2,Table8[],2,0) -> 2021250 | K2: =ROUND(J2*VLOOKUP(F2,Sheet3!$A$106:$C$111,2,FALSE),0) -> 606375 | L2: =J2-K2 -> 1414875 | M2: =ROUND(L2/J2*100, 1) -> 70 | N2: =IF(OR( MONTH(C2)=2, AND(MONTH(C2)=3, D2="UAE"), AND(MONTH(C2)=6, D2="UAE"), AND(MONTH(C2)=7, OR(D2="USA", D2="UK")), MONTH(C2)=9, AND(MONTH(C2)=11, OR(D2="USA", D2="UK")) ), "Yes", "No") -> No | O2: =IF(MONTH(C2)=2, 15, IF(AND(MONTH(C2)=3, D2="UAE"), 20, IF(AND(MONTH(C2)=6, D2="UAE"), 15, IF(AND(MONTH(C2)=7, OR(D2="USA", D2="UK")), 20, IF(AND(MONTH(C2)=11, OR(D2="USA", D2="UK")), 25, 0))))) -> 0 | P2: =IF(MONTH(C2)=2, "Valentine's Day", IF(AND(MONTH(C2)=3, D2="UAE"), "Eid Al Fitr", IF(AND(MONTH(C2)=6, D2="UAE"), "Eid Al Adha", IF(AND(MONTH(C2)=7, OR(D2="USA", D2="UK")), "Summer Sale", IF(MONTH(C2)=9, "Freedom Launch", IF(AND(MONTH(C2)=11, OR(D2="USA", D2="UK")), "Black Friday", "None")))))) -> None | Q2: Stimulated
A3: 2 | B3: January | C3: 45658 | D3: USA | E3: Sephora | F3: Eden Juicy Apple 01 | G3: =_xlfn.CONCAT(F3,"-",D3,) -> Eden Juicy Apple 01-USA | H3: =ROUND(J3/I3,0) -> 11000 | I3: =VLOOKUP(G3,Table4[[SKU-COUNTRY2]:[Price in USD]],2,FALSE) -> 105 | J3: =VLOOKUP(G3,Sheet3!$C$82:$I$100,MATCH(E3,Sheet3!C$82:H$82,0),FALSE) * VLOOKUP(C3,Table8[],2,0) -> 1155000 | K3: =ROUND(J3*VLOOKUP(F3,Sheet3!$A$106:$C$111,2,FALSE),0) -> 358050 | L3: =J3-K3 -> 796950 | M3: =ROUND(L3/J3*100, 1) -> 69 | N3: =IF(OR( MONTH(C3)=2, AND(MONTH(C3)=3, D3="UAE"), AND(MONTH(C3)=6, D3="UAE"), AND(MONTH(C3)=7, OR(D3="USA", D3="UK")), MONTH(C3)=9, AND(MONTH(C3)=11, OR(D3="USA", D3="UK")) ), "Yes", "No") -> No | O3: =IF(MONTH(C3)=2, 15, IF(AND(MONTH(C3)=3, D3="UAE"), 20, IF(AND(MONTH(C3)=6, D3="UAE"), 15, IF(AND(MONTH(C3)=7, OR(D3="USA", D3="UK")), 20, IF(AND(MONTH(C3)=11, OR(D3="USA", D3="UK")), 25, 0))))) -> 0 | P3: =IF(MONTH(C3)=2, "Valentine's Day", IF(AND(MONTH(C3)=3, D3="UAE"), "Eid Al Fitr", IF(AND(MONTH(C3)=6, D3="UAE"), "Eid Al Adha", IF(AND(MONTH(C3)=7, OR(D3="USA", D3="UK")), "Summer Sale", IF(MONTH(C3)=9, "Freedom Launch", IF(AND(MONTH(C3)=11, OR(D3="USA", D3="UK")), "Black Friday", "None")))))) -> None | Q3: Stimulated
A4: 3 | B4: January | C4: 45658 | D4: USA | E4: Sephora | F4: Oudgasm Tobacco Oud 04 | G4: =_xlfn.CONCAT(F4,"-",D4,) -> Oudgasm Tobacco Oud 04-USA | H4: =ROUND(J4/I4,0) -> 7425 | I4: =VLOOKUP(G4,Table4[[SKU-COUNTRY2]:[Price in USD]],2,FALSE) -> 140 | J4: =VLOOKUP(G4,Sheet3!$C$82:$I$100,MATCH(E4,Sheet3!C$82:H$82,0),FALSE) * VLOOKUP(C4,Table8[],2,0) -> 1039500 | K4: =ROUND(J4*VLOOKUP(F4,Sheet3!$A$106:$C$111,2,FALSE),0) -> 363825 | L4: =J4-K4 -> 675675 | M4: =ROUND(L4/J4*100, 1) -> 65 | N4: =IF(OR( MONTH(C4)=2, AND(MONTH(C4)=3, D4="UAE"), AND(MONTH(C4)=6, D4="UAE"), AND(MONTH(C4)=7, OR(D4="USA", D4="UK")), MONTH(C4)=9, AND(MONTH(C4)=11, OR(D4="USA", D4="UK")) ), "Yes", "No") -> No | O4: =IF(MONTH(C4)=2, 15, IF(AND(MONTH(C4)=3, D4="UAE"), 20, IF(AND(MONTH(C4)=6, D4="UAE"), 15, IF(AND(MONTH(C4)=7, OR(D4="USA", D4="UK")), 20, IF(AND(MONTH(C4)=11, OR(D4="USA", D4="UK")), 25, 0))))) -> 0 | P4: =IF(MONTH(C4)=2, "Valentine's Day", IF(AND(MONTH(C4)=3, D4="UAE"), "Eid Al Fitr", IF(AND(MONTH(C4)=6, D4="UAE"), "Eid Al Adha", IF(AND(MONTH(C4)=7, OR(D4="USA", D4="UK")), "Summer Sale", IF(MONTH(C4)=9, "Freedom Launch", IF(AND(MONTH(C4)=11, OR(D4="USA", D4="UK")), "Black Friday", "None")))))) -> None | Q4: Stimulated
A5: 4 | B5: January | C5: 45658 | D5: USA | E5: Sephora | F5: Yum Pistachio Gelato 33 | G5: =_xlfn.CONCAT(F5,"-",D5,) -> Yum Pistachio Gelato 33-USA | H5: =ROUND(J5/I5,0) -> 6600 | I5: =VLOOKUP(G5,Table4[[SKU-COUNTRY2]:[Price in USD]],2,FALSE) -> 105 | J5: =VLOOKUP(G5,Sheet3!$C$82:$I$100,MATCH(E5,Sheet3!C$82:H$82,0),FALSE) * VLOOKUP(C5,Table8[],2,0) -> 693000 | K5: =ROUND(J5*VLOOKUP(F5,Sheet3!$A$106:$C$111,2,FALSE),0) -> 214830 | L5: =J5-K5 -> 478170 | M5: =ROUND(L5/J5*100, 1) -> 69 | N5: =IF(OR( MONTH(C5)=2, AND(MONTH(C5)=3, D5="UAE"), AND(MONTH(C5)=6, D5="UAE"), AND(MONTH(C5)=7, OR(D5="USA", D5="UK")), MONTH(C5)=9, AND(MONTH(C5)=11, OR(D5="USA", D5="UK")) ), "Yes", "No") -> No | O5: =IF(MONTH(C5)=2, 15, IF(AND(MONTH(C5)=3, D5="UAE"), 20, IF(AND(MONTH(C5)=6, D5="UAE"), 15, IF(AND(MONTH(C5)=7, OR(D5="USA", D5="UK")), 20, IF(AND(MONTH(C5)=11, OR(D5="USA", D5="UK")), 25, 0))))) -> 0 | P5: =IF(MONTH(C5)=2, "Valentine's Day", IF(AND(MONTH(C5)=3, D5="UAE"), "Eid Al Fitr", IF(AND(MONTH(C5)=6, D5="UAE"), "Eid Al Adha", IF(AND(MONTH(C5)=7, OR(D5="USA", D5="UK")), "Summer Sale", IF(MONTH(C5)=9, "Freedom Launch", IF(AND(MONTH(C5)=11, OR(D5="USA", D5="UK")), "Black Friday", "None")))))) -> None | Q5: Stimulated
A6: 5 | B6: January | C6: 45658 | D6: USA | E6: Sephora | F6: Freedom Musk Santal 34 | G6: =_xlfn.CONCAT(F6,"-",D6,) -> Freedom Musk Santal 34-USA | H6: =ROUND(J6/I6,0) -> 5500 | I6: =VLOOKUP(G6,Table4[[SKU-COUNTRY2]:[Price in USD]],2,FALSE) -> 105 | J6: =VLOOKUP(G6,Sheet3!$C$82:$I$100,MATCH(E6,Sheet3!C$82:H$82,0),FALSE) * VLOOKUP(C6,Table8[],2,0) -> 577500 | K6: =ROUND(J6*VLOOKUP(F6,Sheet3!$A$106:$C$111,2,FALSE),0) -> 184800 | L6: =J6-K6 -> 392700 | M6: =ROUND(L6/J6*100, 1) -> 68 | N6: =IF(OR( MONTH(C6)=2, AND(MONTH(C6)=3, D6="UAE"), AND(MONTH(C6)=6, D6="UAE"), AND(MONTH(C6)=7, OR(D6="USA", D6="UK")), MONTH(C6)=9, AND(MONTH(C6)=11, OR(D6="USA", D6="UK")) ), "Yes", "No") -> No | O6: =IF(MONTH(C6)=2, 15, IF(AND(MONTH(C6)=3, D6="UAE"), 20, IF(AND(MONTH(C6)=6, D6="UAE"), 15, IF(AND(MONTH(C6)=7, OR(D6="USA", D6="UK")), 20, IF(AND(MONTH(C6)=11, OR(D6="USA", D6="UK")), 25, 0))))) -> 0 | P6: =IF(MONTH(C6)=2, "Valentine's Day", IF(AND(MONTH(C6)=3, D6="UAE"), "Eid Al Fitr", IF(AND(MONTH(C6)=6, D6="UAE"), "Eid Al Adha", IF(AND(MONTH(C6)=7, OR(D6="USA", D6="UK")), "Summer Sale", IF(MONTH(C6)=9, "Freedom Launch", IF(AND(MONTH(C6)=11, OR(D6="USA", D6="UK")), "Black Friday", "None")))))) -> None | Q6: Stimulated
A7: 6 | B7: January | C7: 45658 | D7: USA | E7: Sephora | F7: Musk 12 | G7: =_xlfn.CONCAT(F7,"-",D7,) -> Musk 12-USA | H7: =ROUND(J7/I7,0) -> 2750 | I7: =VLOOKUP(G7,Table4[[SKU-COUNTRY2]:[Price in USD]],2,FALSE) -> 105 | J7: =VLOOKUP(G7,Sheet3!$C$82:$I$100,MATCH(E7,Sheet3!C$82:H$82,0),FALSE) * VLOOKUP(C7,Table8[],2,0) -> 288750 | K7: =ROUND(J7*VLOOKUP(F7,Sheet3!$A$106:$C$111,2,FALSE),0) -> 86625 | L7: =J7-K7 -> 202125 | M7: =ROUND(L7/J7*100, 1) -> 70 | N7: =IF(OR( MONTH(C7)=2, AND(MONTH(C7)=3, D7="UAE"), AND(MONTH(C7)=6, D7="UAE"), AND(MONTH(C7)=7, OR(D7="USA", D7="UK")), MONTH(C7)=9, AND(MONTH(C7)=11, OR(D7="USA", D7="UK")) ), "Yes", "No") -> No | O7: =IF(MONTH(C7)=2, 15, IF(AND(MONTH(C7)=3, D7="UAE"), 20, IF(AND(MONTH(C7)=6, D7="UAE"), 15, IF(AND(MONTH(C7)=7, OR(D7="USA", D7="UK")), 20, IF(AND(MONTH(C7)=11, OR(D7="USA", D7="UK")), 25, 0))))) -> 0 | P7: =IF(MONTH(C7)=2, "Valentine's Day", IF(AND(MONTH(C7)=3, D7="UAE"), "Eid Al Fitr", IF(AND(MONTH(C7)=6, D7="UAE"), "Eid Al Adha", IF(AND(MONTH(C7)=7, OR(D7="USA", D7="UK")), "Summer Sale", IF(MONTH(C7)=9, "Freedom Launch", IF(AND(MONTH(C7)=11, OR(D7="USA", D7="UK")), "Black Friday", "None")))))) -> None | Q7: Stimulated
A8: 7 | B8: January | C8: 45658 | D8: USA | E8: DTC | F8: Vanilla 28 | G8: =_xlfn.CONCAT(F8,"-",D8,) -> Vanilla 28-USA | H8: =ROUND(J8/I8,0) -> 8750 | I8: =VLOOKUP(G8,Table4[[SKU-COUNTRY2]:[Price in USD]],2,FALSE) -> 105 | J8: =VLOOKUP(G8,Sheet3!$C$82:$I$100,MATCH(E8,Sheet3!C$82:H$82,0),FALSE) * VLOOKUP(C8,Table8[],2,0) -> 918750 | K8: =ROUND(J8*VLOOKUP(F8,Sheet3!$A$106:$C$111,2,FALSE),0) -> 275625 | L8: =J8-K8 -> 643125 | M8: =ROUND(L8/J8*100, 1) -> 70 | N8: =IF(OR( MONTH(C8)=2, AND(MONTH(C8)=3, D8="UAE"), AND(MONTH(C8)=6, D8="UAE"), AND(MONTH(C8)=7, OR(D8="USA", D8="UK")), MONTH(C8)=9, AND(MONTH(C8)=11, OR(D8="USA", D8="UK")) ), "Yes", "No") -> No | O8: =IF(MONTH(C8)=2, 15, IF(AND(MONTH(C8)=3, D8="UAE"), 20, IF(AND(MONTH(C8)=6, D8="UAE"), 15, IF(AND(MONTH(C8)=7, OR(D8="USA", D8="UK")), 20, IF(AND(MONTH(C8)=11, OR(D8="USA", D8="UK")), 25, 0))))) -> 0 | P8: =IF(MONTH(C8)=2, "Valentine's Day", IF(AND(MONTH(C8)=3, D8="UAE"), "Eid Al Fitr", IF(AND(MONTH(C8)=6, D8="UAE"), "Eid Al Adha", IF(AND(MONTH(C8)=7, OR(D8="USA", D8="UK")), "Summer Sale", IF(MONTH(C8)=9, "Freedom Launch", IF(AND(MONTH(C8)=11, OR(D8="USA", D8="UK")), "Black Friday", "None")))))) -> None | Q8: Stimulated
A9: 8 | B9: January | C9: 45658 | D9: USA | E9: DTC | F9: Eden Juicy Apple 01 | G9: =_xlfn.CONCAT(F9,"-",D9,) -> Eden Juicy Apple 01-USA | H9: =ROUND(J9/I9,0) -> 5000 | I9: =VLOOKUP(G9,Table4[[SKU-COUNTRY2]:[Price in USD]],2,FALSE) -> 105 | J9: =VLOOKUP(G9,Sheet3!$C$82:$I$100,MATCH(E9,Sheet3!C$82:H$82,0),FALSE) * VLOOKUP(C9,Table8[],2,0) -> 525000 | K9: =ROUND(J9*VLOOKUP(F9,Sheet3!$A$106:$C$111,2,FALSE),0) -> 162750 | L9: =J9-K9 -> 362250 | M9: =ROUND(L9/J9*100, 1) -> 69 | N9: =IF(OR( MONTH(C9)=2, AND(MONTH(C9)=3, D9="UAE"), AND(MONTH(C9)=6, D9="UAE"), AND(MONTH(C9)=7, OR(D9="USA", D9="UK")), MONTH(C9)=9, AND(MONTH(C9)=11, OR(D9="USA", D9="UK")) ), "Yes", "No") -> No | O9: =IF(MONTH(C9)=2, 15, IF(AND(MONTH(C9)=3, D9="UAE"), 20, IF(AND(MONTH(C9)=6, D9="UAE"), 15, IF(AND(MONTH(C9)=7, OR(D9="USA", D9="UK")), 20, IF(AND(MONTH(C9)=11, OR(D9="USA", D9="UK")), 25, 0))))) -> 0 | P9: =IF(MONTH(C9)=2, "Valentine's Day", IF(AND(MONTH(C9)=3, D9="UAE"), "Eid Al Fitr", IF(AND(MONTH(C9)=6, D9="UAE"), "Eid Al Adha", IF(AND(MONTH(C9)=7, OR(D9="USA", D9="UK")), "Summer Sale", IF(MONTH(C9)=9, "Freedom Launch", IF(AND(MONTH(C9)=11, OR(D9="USA", D9="UK")), "Black Friday", "None")))))) -> None | Q9: Stimulated
A10: 9 | B10: January | C10: 45658 | D10: USA | E10: DTC | F10: Oudgasm Tobacco Oud 04 | G10: =_xlfn.CONCAT(F10,"-",D10,) -> Oudgasm Tobacco Oud 04-USA | H10: =ROUND(J10/I10,0) -> 3375 | I10: =VLOOKUP(G10,Table4[[SKU-COUNTRY2]:[Price in USD]],2,FALSE) -> 140 | J10: =VLOOKUP(G10,Sheet3!$C$82:$I$100,MATCH(E10,Sheet3!C$82:H$82,0),FALSE) * VLOOKUP(C10,Table8[],2,0) -> 472500 | K10: =ROUND(J10*VLOOKUP(F10,Sheet3!$A$106:$C$111,2,FALSE),0) -> 165375 | L10: =J10-K10 -> 307125 | M10: =ROUND(L10/J10*100, 1) -> 65 | N10: =IF(OR( MONTH(C10)=2, AND(MONTH(C10)=3, D10="UAE"), AND(MONTH(C10)=6, D10="UAE"), AND(MONTH(C10)=7, OR(D10="USA", D10="UK")), MONTH(C10)=9, AND(MONTH(C10)=11, OR(D10="USA", D10="UK")) ), "Yes", "No") -> No | O10: =IF(MONTH(C10)=2, 15, IF(AND(MONTH(C10)=3, D10="UAE"), 20, IF(AND(MONTH(C10)=6, D10="UAE"), 15, IF(AND(MONTH(C10)=7, OR(D10="USA", D10="UK")), 20, IF(AND(MONTH(C10)=11, OR(D10="USA", D10="UK")), 25, 0))))) -> 0 | P10: =IF(MONTH(C10)=2, "Valentine's Day", IF(AND(MONTH(C10)=3, D10="UAE"), "Eid Al Fitr", IF(AND(MONTH(C10)=6, D10="UAE"), "Eid Al Adha", IF(AND(MONTH(C10)=7, OR(D10="USA", D10="UK")), "Summer Sale", IF(MONTH(C10)=9, "Freedom Launch", IF(AND(MONTH(C10)=11, OR(D10="USA", D10="UK")), "Black Friday", "None")))))) -> None | Q10: Stimulated
A11: 10 | B11: January | C11: 45658 | D11: USA | E11: DTC | F11: Yum Pistachio Gelato 33 | G11: =_xlfn.CONCAT(F11,"-",D11,) -> Yum Pistachio Gelato 33-USA | H11: =ROUND(J11/I11,0) -> 3000 | I11: =VLOOKUP(G11,Table4[[SKU-COUNTRY2]:[Price in USD]],2,FALSE) -> 105 | J11: =VLOOKUP(G11,Sheet3!$C$82:$I$100,MATCH(E11,Sheet3!C$82:H$82,0),FALSE) * VLOOKUP(C11,Table8[],2,0) -> 315000 | K11: =ROUND(J11*VLOOKUP(F11,Sheet3!$A$106:$C$111,2,FALSE),0) -> 97650 | L11: =J11-K11 -> 217350 | M11: =ROUND(L11/J11*100, 1) -> 69 | N11: =IF(OR( MONTH(C11)=2, AND(MONTH(C11)=3, D11="UAE"), AND(MONTH(C11)=6, D11="UAE"), AND(MONTH(C11)=7, OR(D11="USA", D11="UK")), MONTH(C11)=9, AND(MONTH(C11)=11, OR(D11="USA", D11="UK")) ), "Yes", "No") -> No | O11: =IF(MONTH(C11)=2, 15, IF(AND(MONTH(C11)=3, D11="UAE"), 20, IF(AND(MONTH(C11)=6, D11="UAE"), 15, IF(AND(MONTH(C11)=7, OR(D11="USA", D11="UK")), 20, IF(AND(MONTH(C11)=11, OR(D11="USA", D11="UK")), 25, 0))))) -> 0 | P11: =IF(MONTH(C11)=2, "Valentine's Day", IF(AND(MONTH(C11)=3, D11="UAE"), "Eid Al Fitr", IF(AND(MONTH(C11)=6, D11="UAE"), "Eid Al Adha", IF(AND(MONTH(C11)=7, OR(D11="USA", D11="UK")), "Summer Sale", IF(MONTH(C11)=9, "Freedom Launch", IF(AND(MONTH(C11)=11, OR(D11="USA", D11="UK")), "Black Friday", "None")))))) -> None | Q11: Stimulated
A12: 11 | B12: January | C12: 45658 | D12: USA | E12: DTC | F12: Freedom Musk Santal 34 | G12: =_xlfn.CONCAT(F12,"-",D12,) -> Freedom Musk Santal 34-USA | H12: =ROUND(J12/I12,0) -> 2500 | I12: =VLOOKUP(G12,Table4[[SKU-COUNTRY2]:[Price in USD]],2,FALSE) -> 105 | J12: =VLOOKUP(G12,Sheet3!$C$82:$I$100,MATCH(E12,Sheet3!C$82:H$82,0),FALSE) * VLOOKUP(C12,Table8[],2,0) -> 262500 | K12: =ROUND(J12*VLOOKUP(F12,Sheet3!$A$106:$C$111,2,FALSE),0) -> 84000 | L12: =J12-K12 -> 178500 | M12: =ROUND(L12/J12*100, 1) -> 68 | N12: =IF(OR( MONTH(C12)=2, AND(MONTH(C12)=3, D12="UAE"), AND(MONTH(C12)=6, D12="UAE"), AND(MONTH(C12)=7, OR(D12="USA", D12="UK")), MONTH(C12)=9, AND(MONTH(C12)=11, OR(D12="USA", D12="UK")) ), "Yes", "No") -> No | O12: =IF(MONTH(C12)=2, 15, IF(AND(MONTH(C12)=3, D12="UAE"), 20, IF(AND(MONTH(C12)=6, D12="UAE"), 15, IF(AND(MONTH(C12)=7, OR(D12="USA", D12="UK")), 20, IF(AND(MONTH(C12)=11, OR(D12="USA", D12="UK")), 25, 0))))) -> 0 | P12: =IF(MONTH(C12)=2, "Valentine's Day", IF(AND(MONTH(C12)=3, D12="UAE"), "Eid Al Fitr", IF(AND(MONTH(C12)=6, D12="UAE"), "Eid Al Adha", IF(AND(MONTH(C12)=7, OR(D12="USA", D12="UK")), "Summer Sale", IF(MONTH(C12)=9, "Freedom Launch", IF(AND(MONTH(C12)=11, OR(D12="USA", D12="UK")), "Black Friday", "None")))))) -> None | Q12: Stimulated
A13: 12 | B13: January | C13: 45658 | D13: USA | E13: DTC | F13: Musk 12 | G13: =_xlfn.CONCAT(F13,"-",D13,) -> Musk 12-USA | H13: =ROUND(J13/I13,0) -> 1250 | I13: =VLOOKUP(G13,Table4[[SKU-COUNTRY2]:[Price in USD]],2,FALSE) -> 105 | J13: =VLOOKUP(G13,Sheet3!$C$82:$I$100,MATCH(E13,Sheet3!C$82:H$82,0),FALSE) * VLOOKUP(C13,Table8[],2,0) -> 131250 | K13: =ROUND(J13*VLOOKUP(F13,Sheet3!$A$106:$C$111,2,FALSE),0) -> 39375 | L13: =J13-K13 -> 91875 | M13: =ROUND(L13/J13*100, 1) -> 70 | N13: =IF(OR( MONTH(C13)=2, AND(MONTH(C13)=3, D13="UAE"), AND(MONTH(C13)=6, D13="UAE"), AND(MONTH(C13)=7, OR(D13="USA", D13="UK")), MONTH(C13)=9, AND(MONTH(C13)=11, OR(D13="USA", D13="UK")) ), "Yes", "No") -> No | O13: =IF(MONTH(C13)=2, 15, IF(AND(MONTH(C13)=3, D13="UAE"), 20, IF(AND(MONTH(C13)=6, D13="UAE"), 15, IF(AND(MONTH(C13)=7, OR(D13="USA", D13="UK")), 20, IF(AND(MONTH(C13)=11, OR(D13="USA", D13="UK")), 25, 0))))) -> 0 | P13: =IF(MONTH(C13)=2, "Valentine's Day", IF(AND(MONTH(C13)=3, D13="UAE"), "Eid Al Fitr", IF(AND(MONTH(C13)=6, D13="UAE"), "Eid Al Adha", IF(AND(MONTH(C13)=7, OR(D13="USA", D13="UK")), "Summer Sale", IF(MONTH(C13)=9, "Freedom Launch", IF(AND(MONTH(C13)=11, OR(D13="USA", D13="UK")), "Black Friday", "None")))))) -> None | Q13: Stimulated
... A865: 864 | B865: December | C865: 45992 | D865: UAE | E865: Wholesale | F865: Musk 12 | G865: =_xlfn.CONCAT(F865,"-",D865,) -> Musk 12-UAE | H865: =ROUND(J865/I865,0) -> 282 | I865: =VLOOKUP(G865,Table4[[SKU-COUNTRY2]:[Price in USD]],2,FALSE) -> 113.4 | J865: =VLOOKUP(G865,Sheet3!$C$82:$I$100,MATCH(E865,Sheet3!C$82:H$82,0),FALSE) * VLOOKUP(C865,Table8[],2,0) -> 32000 | K865: =ROUND(J865*VLOOKUP(F865,Sheet3!$A$106:$C$111,2,FALSE),0) -> 9600 | L865: =J865-K865 -> 22400 | M865: =ROUND(L865/J865*100, 1) -> 70 | N865: =IF(OR( MONTH(C865)=2, AND(MONTH(C865)=3, D865="UAE"), AND(MONTH(C865)=6, D865="UAE"), AND(MONTH(C865)=7, OR(D865="USA", D865="UK")), MONTH(C865)=9, AND(MONTH(C865)=11, OR(D865="USA", D865="UK")) ), "Yes", "No") -> No | O865: =IF(MONTH(C865)=2, 15, IF(AND(MONTH(C865)=3, D865="UAE"), 20, IF(AND(MONTH(C865)=6, D865="UAE"), 15, IF(AND(MONTH(C865)=7, OR(D865="USA", D865="UK")), 20, IF(AND(MONTH(C865)=11, OR(D865="USA", D865="UK")), 25, 0))))) -> 0 | P865: =IF(MONTH(C865)=2, "Valentine's Day", IF(AND(MONTH(C865)=3, D865="UAE"), "Eid Al Fitr", IF(AND(MONTH(C865)=6, D865="UAE"), "Eid Al Adha", IF(AND(MONTH(C865)=7, OR(D865="USA", D865="UK")), "Summer Sale", IF(MONTH(C865)=9, "Freedom Launch", IF(AND(MONTH(C865)=11, OR(D865="USA", D865="UK")), "Black Friday", "None")))))) -> None | Q865: Stimulated

Sheet Sheet3
A1: Country % of Revenue | B1: Country | C1: Sephora | D1: DTC | E1: Travel Retail | F1: Wholesale | G1: Monthly Revenue in USD
A2: US % of Revenue | B2: USA | C2: 0.55 | D2: 0.25 | E2: 0.12 | F2: 0.08 | G2: 14000000
A3: UK % of Revenue | B3: UK | C3: 0.4 | D3: 0.2 | E3: 0.15 | F3: 0.25 | G3: 2000000
A4: UAE % of Revenue | B4: UAE | C4: 0.45 | D4: 0.25 | E4: 0.2 | F4: 0.1 | G4: 2500000 | S4: SKU | T4: Selling_Price_USD | U4: US % of Revenue
S5: Vanilla 28 | U5: 0.35
S6: Eden Juicy Apple 01 | U6: 0.2
A7: Country's Monthly Revenue | B7: Sephora | C7: DTC | D7: Travel Retail | E7: Wholesale | S7: Oudgasm Tobacco 28 | U7: 0.18
A8: USA | B8: =$G2*C2 -> 7700000 | C8: =$G2*D2 -> 3500000 | D8: =$G2*E2 -> 1680000 | E8: =$G2*F2 -> 1120000 | S8: Yum Pistachio Gelato 33 | U8: 0.12
A9: UK | B9: =$G3*C3 -> 800000 | C9: =$G3*D3 -> 400000 | D9: =$G3*E3 -> 300000 | E9: =$G3*F3 -> 500000 | S9: Freedom Musk Santal 34 | U9: 0.1
A10: UAE | B10: =$G4*C4 -> 1125000 | C10: =$G4*D4 -> 625000 | D10: =$G4*E4 -> 500000 | E10: =$G4*F4 -> 250000 | S10: Musk 12 | U10: 0.05
D14: Monthly Revenue | E14: Monthly Revenue | F14: Monthly Revenue | G14: Monthly Revenue
A16: SKU | B16: Country | C16: SKU-COUNTRY | D16: % of Revenue | E16: Sephora | F16: DTC | G16: Travel Retail | H16: Wholesale | I16: SKU-COUNTRY2 | J16: Price in USD
A17: Vanilla 28 | B17: USA | C17: Vanilla 28-USA | D17: 0.35 | E17: =D$17*B8 -> 2695000 | F17: =$D$17*C8 -> 1225000 | G17: =$D$17*D8 -> 588000 | H17: =$D$17*E8 -> 392000 | I17: =_xlfn.CONCAT(Table4[[#This Row],[SKU]],"-",Table4[[#This Row],[Country]]) -> Vanilla 28-USA | J17: =VLOOKUP(Table4[[#This Row],[SKU-COUNTRY2]],Table7[[SKU-COUNTRY]:[Final Price in USD]],3,FALSE) -> 105
A18: Vanilla 28 | B18: UK | C18: Vanilla 28-UK | D18: 0.3 | E18: =$D$18*B9 -> 240000 | F18: =$D$18*C9 -> 120000 | G18: =$D$18*D9 -> 90000 | H18: =$D$18*E9 -> 150000 | I18: =_xlfn.CONCAT(Table4[[#This Row],[SKU]],"-",Table4[[#This Row],[Country]]) -> Vanilla 28-UK | J18: =VLOOKUP(Table4[[#This Row],[SKU-COUNTRY2]],Table7[[SKU-COUNTRY]:[Final Price in USD]],3,FALSE) -> 101.6
A19: Vanilla 28 | B19: UAE | C19: Vanilla 28-UAE | D19: 0.2 | E19: =$D$19*B10 -> 225000 | F19: =$D$19*C10 -> 125000 | G19: =$D$19*D10 -> 100000 | H19: =$D$19*E10 -> 50000 | I19: =_xlfn.CONCAT(Table4[[#This Row],[SKU]],"-",Table4[[#This Row],[Country]]) -> Vanilla 28-UAE | J19: =VLOOKUP(Table4[[#This Row],[SKU-COUNTRY2]],Table7[[SKU-COUNTRY]:[Final Price in USD]],3,FALSE) -> 113.4
A20: Eden Juicy Apple 01 | B20: USA | C20: Eden Juicy Apple 01-USA | D20: 0.2 | E20: =$D$20*B8 -> 1540000 | F20: =$D$20*C8 -> 700000 | G20: =$D$20*D8 -> 336000 | H20: =$D$20*E8 -> 224000 | I20: =_xlfn.CONCAT(Table4[[#This Row],[SKU]],"-",Table4[[#This Row],[Country]]) -> Eden Juicy Apple 01-USA | J20: =VLOOKUP(Table4[[#This Row],[SKU-COUNTRY2]],Table7[[SKU-COUNTRY]:[Final Price in USD]],3,FALSE) -> 105
A21: Eden Juicy Apple 01 | B21: UK | C21: Eden Juicy Apple 01-UK | D21: 0.22 | E21: =$D$21*B9 -> 176000 | F21: =$D$21*C9 -> 88000 | G21: =$D$21*D9 -> 66000 | H21: =$D$21*E9 -> 110000 | I21: =_xlfn.CONCAT(Table4[[#This Row],[SKU]],"-",Table4[[#This Row],[Country]]) -> Eden Juicy Apple 01-UK | J21: =VLOOKUP(Table4[[#This Row],[SKU-COUNTRY2]],Table7[[SKU-COUNTRY]:[Final Price in USD]],3,FALSE) -> 101.6
A22: Eden Juicy Apple 01 | B22: UAE | C22: Eden Juicy Apple 01-UAE | D22: 0.15 | E22: =$D$22*B10 -> 168750 | F22: =$D$22*C10 -> 93750 | G22: =$D$22*D10 -> 75000 | H22: =$D$22*E10 -> 37500 | I22: =_xlfn.CONCAT(Table4[[#This Row],[SKU]],"-",Table4[[#This Row],[Country]]) -> Eden Juicy Apple 01-UAE | J22: =VLOOKUP(Table4[[#This Row],[SKU-COUNTRY2]],Table7[[SKU-COUNTRY]:[Final Price in USD]],3,FALSE) -> 113.4
A23: Oudgasm Tobacco Oud 04 | B23: USA | C23: Oudgasm Tobacco Oud 04-USA | D23: 0.18 | E23: =$D$23*B8 -> 1386000 | F23: =$D$23*C8 -> 630000 | G23: =$D$23*D8 -> 302400 | H23: =$D$23*E8 -> 201600 | I23: =_xlfn.CONCAT(Table4[[#This Row],[SKU]],"-",Table4[[#This Row],[Country]]) -> Oudgasm Tobacco Oud 04-USA | J23: =VLOOKUP(Table4[[#This Row],[SKU-COUNTRY2]],Table7[[SKU-COUNTRY]:[Final Price in USD]],3,FALSE) -> 140
A24: Oudgasm Tobacco Oud 04 | B24: UK | C24: Oudgasm Tobacco Oud 04-UK | D24: 0.18 | E24: =$D$24*B9 -> 144000 | F24: =$D$24*C9 -> 72000 | G24: =$D$24*D9 -> 54000 | H24: =$D$24*E9 -> 90000 | I24: =_xlfn.CONCAT(Table4[[#This Row],[SKU]],"-",Table4[[#This Row],[Country]]) -> Oudgasm Tobacco Oud 04-UK | J24: =VLOOKUP(Table4[[#This Row],[SKU-COUNTRY2]],Table7[[SKU-COUNTRY]:[Final Price in USD]],3,FALSE) -> 151.13
A25: Oudgasm Tobacco Oud 04 | B25: UAE | C25: Oudgasm Tobacco Oud 04-UAE | D25: 0.35 | E25: =$D$25*B10 -> 393750 | F25: =$D$25*C10 -> 218750 | G25: =$D$25*D10 -> 175000 | H25: =$D$25*E10 -> 87500 | I25: =_xlfn.CONCAT(Table4[[#This Row],[SKU]],"-",Table4[[#This Row],[Country]]) -> Oudgasm Tobacco Oud 04-UAE | J25: =VLOOKUP(Table4[[#This Row],[SKU-COUNTRY2]],Table7[[SKU-COUNTRY]:[Final Price in USD]],3,FALSE) -> 148.77
A26: Yum Pistachio Gelato 33 | B26: USA | C26: Yum Pistachio Gelato 33-USA | D26: 0.12 | E26: =$D$26*B8 -> 924000 | F26: =$D$26*C8 -> 420000 | G26: =$D$26*D8 -> 201600 | H26: =$D$26*E8 -> 134400 | I26: =_xlfn.CONCAT(Table4[[#This Row],[SKU]],"-",Table4[[#This Row],[Country]]) -> Yum Pistachio Gelato 33-USA | J26: =VLOOKUP(Table4[[#This Row],[SKU-COUNTRY2]],Table7[[SKU-COUNTRY]:[Final Price in USD]],3,FALSE) -> 105
A27: Yum Pistachio Gelato 33 | B27: UK | C27: Yum Pistachio Gelato 33-UK | D27: 0.13 | E27: =$D$27*B9 -> 104000 | F27: =$D$27*C9 -> 52000 | G27: =$D$27*D9 -> 39000 | H27: =$D$27*E9 -> 65000 | I27: =_xlfn.CONCAT(Table4[[#This Row],[SKU]],"-",Table4[[#This Row],[Country]]) -> Yum Pistachio Gelato 33-UK | J27: =VLOOKUP(Table4[[#This Row],[SKU-COUNTRY2]],Table7[[SKU-COUNTRY]:[Final Price in USD]],3,FALSE) -> 101.6
A28: Yum Pistachio Gelato 33 | B28: UAE | C28: Yum Pistachio Gelato 33-UAE | D28: 0.12 | E28: =$D$28*B10 -> 135000 | F28: =$D$28*C10 -> 75000 | G28: =$D$28*D10 -> 60000 | H28: =$D$28*E10 -> 30000 | I28: =_xlfn.CONCAT(Table4[[#This Row],[SKU]],"-",Table4[[#This Row],[Country]]) -> Yum Pistachio Gelato 33-UAE | J28: =VLOOKUP(Table4[[#This Row],[SKU-COUNTRY2]],Table7[[SKU-COUNTRY]:[Final Price in USD]],3,FALSE) -> 113.4
A29: Freedom Musk Santal 34 | B29: USA | C29: Freedom Musk Santal 34-USA | D29: 0.1 | E29: =$D$29*B8 -> 770000 | F29: =$D$29*C8 -> 350000 | G29: =$D$29*D8 -> 168000 | H29: =$D$29*E8 -> 112000 | I29: =_xlfn.CONCAT(Table4[[#This Row],[SKU]],"-",Table4[[#This Row],[Country]]) -> Freedom Musk Santal 34-USA | J29: =VLOOKUP(Table4[[#This Row],[SKU-COUNTRY2]],Table7[[SKU-COUNTRY]:[Final Price in USD]],3,FALSE) -> 105
A30: Freedom Musk Santal 34 | B30: UK | C30: Freedom Musk Santal 34-UK | D30: 0.1 | E30: =$D$30*B9 -> 80000 | F30: =$D$30*C9 -> 40000 | G30: =$D$30*D9 -> 30000 | H30: =$D$30*E9 -> 50000 | I30: =_xlfn.CONCAT(Table4[[#This Row],[SKU]],"-",Table4[[#This Row],[Country]]) -> Freedom Musk Santal 34-UK | J30: =VLOOKUP(Table4[[#This Row],[SKU-COUNTRY2]],Table7[[SKU-COUNTRY]:[Final Price in USD]],3,FALSE) -> 101.6
A31: Freedom Musk Santal 34 | B31: UAE | C31: Freedom Musk Santal 34-UAE | D31: 0.1 | E31: =$D$31*B10 -> 112500 | F31: =$D$31*C10 -> 62500 | G31: =$D$31*D10 -> 50000 | H31: =$D$31*E10 -> 25000 | I31: =_xlfn.CONCAT(Table4[[#This Row],[SKU]],"-",Table4[[#This Row],[Country]]) -> Freedom Musk Santal 34-UAE | J31: =VLOOKUP(Table4[[#This Row],[SKU-COUNTRY2]],Table7[[SKU-COUNTRY]:[Final Price in USD]],3,FALSE) -> 113.4
A32: Musk 12 | B32: USA | C32: Musk 12-USA | D32: 0.05 | E32: =$D$32*B8 -> 385000 | F32: =$D$32*C8 -> 175000 | G32: =$D$32*D8 -> 84000 | H32: =$D$32*E8 -> 56000 | I32: =_xlfn.CONCAT(Table4[[#This Row],[SKU]],"-",Table4[[#This Row],[Country]]) -> Musk 12-USA | J32: =VLOOKUP(Table4[[#This Row],[SKU-COUNTRY2]],Table7[[SKU-COUNTRY]:[Final Price in USD]],3,FALSE) -> 105
A33: Musk 12 | B33: UK | C33: Musk 12-UK | D33: 0.07 | E33: =$D$33*B9 -> 56000 | F33: =$D$33*C9 -> 28000 | G33: =$D$33*D9 -> 21000 | H33: =$D$33*E9 -> 35000 | I33: =_xlfn.CONCAT(Table4[[#This Row],[SKU]],"-",Table4[[#This Row],[Country]]) -> Musk 12-UK | J33: =VLOOKUP(Table4[[#This Row],[SKU-COUNTRY2]],Table7[[SKU-COUNTRY]:[Final Price in USD]],3,FALSE) -> 101.6
A34: Musk 12 | B34: UAE | C34: Musk 12-UAE | D34: 0.08 | E34: =$D$34*B10 -> 90000 | F34: =$D$34*C10 -> 50000 | G34: =$D$34*D10 -> 40000 | H34: =$D$34*E10 -> 20000 | I34: =_xlfn.CONCAT(Table4[[#This Row],[SKU]],"-",Table4[[#This Row],[Country]]) -> Musk 12-UAE | J34: =VLOOKUP(Table4[[#This Row],[SKU-COUNTRY2]],Table7[[SKU-COUNTRY]:[Final Price in USD]],3,FALSE) -> 113.4
A41: SKU | B41: Country | C41: SKU-COUNTRY | D41: usd/gbp/ aed | E41: Final Price in USD
A42: Vanilla 28 | B42: USA | C42: =_xlfn.CONCAT(Table7[[#This Row],[SKU]],"-",Table7[[#This Row],[Country]]) -> Vanilla 28-USA | D42: 105 | E42: =D42*IF(B42="USA",1,IF(B42="UK",1.27,0.27)) -> 105
A43: Eden Juicy Apple 01 | B43: USA | C43: =_xlfn.CONCAT(Table7[[#This Row],[SKU]],"-",Table7[[#This Row],[Country]]) -> Eden Juicy Apple 01-USA | D43: 105 | E43: =D43*IF(B43="USA",1,IF(B43="UK",1.27,0.27)) -> 105
A44: Oudgasm Tobacco Oud 04 | B44: USA | C44: =_xlfn.CONCAT(Table7[[#This Row],[SKU]],"-",Table7[[#This Row],[Country]]) -> Oudgasm Tobacco Oud 04-USA | D44: 140 | E44: =D44*IF(B44="USA",1,IF(B44="UK",1.27,0.27)) -> 140
A45: Yum Pistachio Gelato 33 | B45: USA | C45: =_xlfn.CONCAT(Table7[[#This Row],[SKU]],"-",Table7[[#This Row],[Country]]) -> Yum Pistachio Gelato 33-USA | D45: 105 | E45: =D45*IF(B45="USA",1,IF(B45="UK",1.27,0.27)) -> 105
A46: Freedom Musk Santal 34 | B46: USA | C46: =_xlfn.CONCAT(Table7[[#This Row],[SKU]],"-",Table7[[#This Row],[Country]]) -> Freedom Musk Santal 34-USA | D46: 105 | E46: =D46*IF(B46="USA",1,IF(B46="UK",1.27,0.27)) -> 105
A47: Musk 12 | B47: USA | C47: =_xlfn.CONCAT(Table7[[#This Row],[SKU]],"-",Table7[[#This Row],[Country]]) -> Musk 12-USA | D47: 105 | E47: =D47*IF(B47="USA",1,IF(B47="UK",1.27,0.27)) -> 105
A48: Vanilla 28 | B48: UK | C48: =_xlfn.CONCAT(Table7[[#This Row],[SKU]],"-",Table7[[#This Row],[Country]]) -> Vanilla 28-UK | D48: 80 | E48: =D48*IF(B48="USA",1,IF(B48="UK",1.27,0.27)) -> 101.6
A49: Eden Juicy Apple 01 | B49: UK | C49: =_xlfn.CONCAT(Table7[[#This Row],[SKU]],"-",Table7[[#This Row],[Country]]) -> Eden Juicy Apple 01-UK | D49: 80 | E49: =D49*IF(B49="USA",1,IF(B49="UK",1.27,0.27)) -> 101.6
A50: Oudgasm Tobacco Oud 04 | B50: UK | C50: =_xlfn.CONCAT(Table7[[#This Row],[SKU]],"-",Table7[[#This Row],[Country]]) -> Oudgasm Tobacco Oud 04-UK | D50: 119 | E50: =D50*IF(B50="USA",1,IF(B50="UK",1.27,0.27)) -> 151.13
...

Sheet MAIN REFERENCE
A1: Market | B1: Monthly Baseline | C1: Reasoning | F1: Kayali's US luxury perfume market value was estimated at $7.5 billion in 2024. Kayali was confirmed as the #1 fragrance brand at Sephora in H1 2025 and hit $100M in US sales in 7 months — so roughly $14M per month in the US across all channels.
A2: USA | B2: $14,000,000 | C2: Confirmed $100M in 7 months — largest market
A3: UAE | B3: $2,500,000 | C3: Home market — own stores + Sephora AE + strong cultural demand
A4: UK | B4: $2,000,000 | C4: Established market — Sephora UK + Cult Beauty + ASOS + Selfridges
F6: Kayali's US luxury perfume market value was estimated at $7.5 billion in 2024. Kayali was confirmed as the #1 fragrance brand at Sephora in H1 2025 and hit $100M in US sales in 7 months — so roughly $14M per month in the US across all channels.
A8: Channel | B8: US % of Revenue | C8: UK % of Revenue | D8: UAE % of Revenue | F8: Why Travel Retail is higher for UAE: Dubai and Abu Dhabi airports are among the world's busiest luxury retail hubs — fragrance travel retail is a major channel in the UAE specifically.
A9: Sephora | B9: 0.55 | C9: 0.4 | D9: 0.45
A10: DTC | B10: 0.25 | C10: 0.2 | D10: 0.25 | F10: Why Wholesale is higher for UK: The presence of Cult Beauty, ASOS and Selfridges as separate retail partners means a larger share of UK revenue flows through wholesale accounts compared to the US where Sephora has near-exclusivity.
A11: Travel_Retail | B11: 0.12 | C11: 0.15 | D11: 0.2
A12: Wholesale | B12: 0.08 | C12: 0.25 | D12: 0.1
A13: Total | B13: 1 | C13: 1 | D13: 1
A16: SKU | B16: US % of Revenue | C16: UK % of Revenue | D16: UAE % of Revenue
A17: Vanilla 28 | B17: 0.35 | C17: 0.3 | D17: 0.2
A18: Eden Juicy Apple 01 | B18: 0.2 | C18: 0.22 | D18: 0.15
A19: Oudgasm Tobacco Oud 04 | B19: 0.18 | C19: 0.18 | D19: 0.35
A20: Yum Pistachio Gelato 33 | B20: 0.12 | C20: 0.13 | D20: 0.12
A21: Freedom Musk Santal 34 | B21: 0.1 | C21: 0.1 | D21: 0.1
A22: Musk 12 | B22: 0.05 | C22: 0.07 | D22: 0.08
A23: Total | B23: 1 | C23: 1 | D23: 1
A26: SKU | B26: Selling_Price_USD | C26: GBP | D26: AED | G26: Use these standard 2024 average exchange rates:
A27: Vanilla 28 | B27: 105 | C27: 80 | D27: 420
A28: Eden Juicy Apple 01 | B28: 105 | C28: 80 | D28: 420 | G28: 1 GBP = 1.27 USD
A29: Oudgasm Tobacco Oud 04 | B29: 140 | C29: 119 | D29: 551 | G29: 1 AED = 0.27 USD
A30: Yum Pistachio Gelato 33 | B30: 105 | C30: 80 | D30: 420
A31: Freedom Musk Santal 34 | B31: 105 | C31: 80 | D31: 420
A32: Musk 12 | B32: 105 | C32: 80 | D32: 420
A38: Month | B38: Multiplier | C38: Reasoning
A39: 45658 | B39: 0.75 | C39: Post-holiday spending hangover. Consumers just spent heavily in November and December on gifts. January is consistently the slowest retail month globally across all luxury categories.
A40: 45689 | B40: 1.2 | C40: Valentine's Day. Fragrance is the #1 gifting category for Valentine's Day worldwide. Kayali specifically runs Valentine's promotions — we already captured this in your Campaign_Name column.
A41: 45717 | B41: 0.9 | C41: Return to normal. No major gifting occasion or holiday. Slight recovery from January but still below baseline.
A42: 45748 | B42: 0.85 | C42: Quiet month commercially. In UAE this overlaps with post-Ramadan period where spending patterns normalise after Eid gifting surge.
A43: 45778 | B43: 0.95 | C43: Slight pickup. Mother's Day in US and UK falls in May — fragrance is a popular Mother's Day gift but not as impactful as Valentine's or Christmas.
A44: 45809 | B44: 0.9 | C44: Early summer slowdown. Consumers shift spending toward travel and experiences rather than luxury goods.
A45: 45839 | B45: 0.85 | C45: Peak summer slowdown. Lowest non-January month. In UAE this is also peak summer heat season when residents travel abroad reducing local retail foot traffic significantly.
A46: 45870 | B46: 0.9 | C46: Slight recovery. Back to school period in US and UK. UAE residents return from summer travel. Retail begins rebuilding momentum.
A47: 45901 | B47: 1 | C47: Baseline month. No major events but autumn retail season begins. This is also when Kayali's Freedom collection launch is set — new launches always drive a spike in brand awareness and traffic.
A48: 45931 | B48: 1.1 | C48: Pre-holiday buildup begins. Consumers start Christmas shopping earlier every year. Retailers begin promoting gift sets and holiday editions. In UAE this also captures early preparation for National Day gifting season.
A49: 45962 | B49: 1.4 | C49: Black Friday and Cyber Monday. Biggest single sales event of the year in US and UK. Kayali runs significant promotions — already captured in your Campaign column. November is when holiday gifting purchases accelerate sharply.
A50: 45992 | B50: 1.6 | C50: Peak Christmas and holiday season. Fragrance is the #1 luxury gift category globally. Every retailer pushes fragrance gift sets heavily. In UAE December also captures National Day (December 2nd) gifting which is significant for home market sales.
A55: Campaign | B55: Months Active | C55: Markets | D55: Discount %
...

Sheet Links
A1: "All revenue figures reported in USD. UK prices converted at GBP/USD 1.27. UAE prices converted at AED/USD 0.27. Exchange rates based on 2024 annual averages."

Sheet Sheet1
A1: USA
A2: UK
A3: UAE
A6: DTC, Sephora, Travel Retail, Wholesale
A7: DTC
A8: Sephora
A9: Travel Retail
A10: Wholesale
D11: 45658 | E11: =IF(D11=1-1-2025,1,0) -> 0
